Workbook

Sheet BOM
A1: XBOX_V2.5 主板电子BOM
A2: 序号 | B2: materiel Name | C2: 物料描述 | D2: 物料编码(part number) | E2: 位号 | F2: 用量 | G2: 数量/PCS
A3: 1 | B3: 电阻 | C3: RES,0Ω,±5%,1/16W,0402,0402WGJ0TCE,ROHS,UniOhm | D3: 0402WGJ0000TCE | E3: L2 L3 L4 L800 R3 R39 R41 R45 R53 R63 R64 R65 R66 R69 R72 R76 R77 R78 R79 R80 R81 R82 R83 R84 R85 R86 R87 R92 R94 R115 R120 R605 R606 R607 R11 | F3: 35 | G3: =VLOOKUP(C3,[1]物料下单2024!$B$1:$H$65536,7,FALSE) -> 20000
A4: 2 | B4: 电阻 | C4: RES,47Ω,±5%,1/16W,0402,0402WGJ040TCE,ROHS,UniOhm | D4: 0402WGJ0470TCE | E4: R25 R28 R229 R230 | F4: 4 | G4: =VLOOKUP(C4,[1]物料下单2024!$B$1:$H$65536,7,FALSE) -> #N/A
A5: 2 | B5: 电阻 | C5: RES,200Ω,±5%,1/16W,0402,0402WGJ0201TCE,ROHS,UniOhm | D5: 0402WGJ0201TCE | E5: R7 R12 R30 R31 R32 R37 R70 R74 R75 R90 R91 R236 | F5: 12 | G5: =VLOOKUP(C5,[1]物料下单2024!$B$1:$H$65536,7,FALSE) -> 10000
A6: 3 | B6: 电阻 | C6: RES,1KΩ,±5%,1/16W,0402,0402WGJ1001TCE,ROHS,UniOhm | D6: 0402WGJ0102TCE | E6: R15 R16 R17 R19 R35 R43 R46 R47 R49 R51 R52 R56 R59 R73 R95 R96 R97 R105 R112 R117 R124 R130 R134 R400 | F6: 24 | G6: =VLOOKUP(C6,[1]物料下单2024!$B$1:$H$65536,7,FALSE) -> 10000
A7: 4 | B7: 电阻 | C7: RES,3.3KΩ,±5%,1/16W,0402,0402WGJ3301TCE,ROHS,UniOhm | D7: 0402WGJ0332TCE | E7: R71 | F7: 1 | G7: =VLOOKUP(C7,[1]物料下单2024!$B$1:$H$65536,7,FALSE) -> #N/A
A8: 4 | B8: 电阻 | C8: RES,4.7KΩ,±5%,1/16W,0402,0402WGJ4701TCE,ROHS,UniOhm | D8: 0402WGJ0472TCE | E8: R23 R61 R62 R601 R603 | F8: 5 | G8: =VLOOKUP(C8,[1]物料下单2024!$B$1:$H$65536,7,FALSE) -> 10000
A9: 5 | B9: 电阻 | C9: RES,10KΩ,±5%,1/16W,0402,0402WGJ0103TCE,ROHS,UniOhm | D9: 0402WGJ0103TCE | E9: R2 R9 R18 R21 R24 R26 R36 R42 R44 R48 R50 R54 R57 R58 R60 R99 R101 R102 R103 R104 R106 R107 R108 R109 R110 R111 R114 R116 R118 R121 R125 R128 R129 R132 R133 R145 R172 R173 R231 R252 R604 | F9: 41 | G9: =VLOOKUP(C9,[1]物料下单2024!$B$1:$H$65536,7,FALSE) -> 20000
A10: 7 | B10: 电阻 | C10: RES,100KΩ,±5%,1/16W,0402,0402WGJ1003TCE,ROHS,UniOhm | D10: 0402WGJ0104TCE | E10: R4 R14 R98 R100 R113 R1 | F10: 6 | G10: =VLOOKUP(C10,[1]物料下单2024!$B$1:$H$65536,7,FALSE) -> 10000
A11: 8 | B11: 电阻 | C11: RES,1MΩ,±5%,1/16W,0402,0402WGJ0105TCE,ROHS,UniOhm | D11: 0402WGJ0105TCE | E11: R55 R123 | F11: 2 | G11: =VLOOKUP(C11,[1]物料下单2024!$B$1:$H$65536,7,FALSE) -> 10000
A12: 9 | B12: 电阻 | C12: RES,1.2KΩ,±1%,1/16W,0402,0402WGF1201TCE,ROHS,UniOhm | D12: 0402WGF1201TCE | E12: R171 | F12: 1 | G12: =VLOOKUP(C12,[1]物料下单2024!$B$1:$H$65536,7,FALSE) -> 10000
A13: 10 | B13: 电阻 | C13: RES,6.8KΩ,±1%,1/16W,0402,0402WGF6801TCE,ROHS,UniOhm | D13: 0402WGF6801TCE | E13: R170 | F13: 1 | G13: =VLOOKUP(C13,[1]物料下单2024!$B$1:$H$65536,7,FALSE) -> 10000
A14: 11 | B14: 电阻 | C14: RES,10KΩ,±1%,1/16W,0402,0402WGF1002TCE,ROHS,UniOhm | D14: 0402WGF1002TCE | E14: R314 | F14: 1 | G14: =VLOOKUP(C14,[1]物料下单2024!$B$1:$H$65536,7,FALSE) -> 10000
... A36: 31 | B36: 晶体 | C36: 晶振,32.768KHZ,12.5PF,±20PPm,FC-135 | D36: SF32WK32768D31T002 | E36: X1 | F36: 1 | G36: =VLOOKUP(C36,[1]物料下单2024!$B$1:$H$65536,7,FALSE) -> 3000
A37: 32 | B37: 晶体 | C37: 无源晶振,12MHz,±10ppm,负载电容20PF,SMD3225,RoHS | D37: 3206120001 | E37: X101 | F37: 1 | G37: =VLOOKUP(C37,[1]物料下单2024!$B$1:$H$65536,7,FALSE) -> 4000
A38: 33 | B38: 晶体 | C38: 无源晶振,24MHz,±10ppm,负载电容12PF,3.2*2.5,RoHS | D38: 3225 24M | E38: X2 | F38: 1 | G38: =VLOOKUP(C38,[1]物料下单2024!$B$1:$H$65536,7,FALSE) -> 3000
A39: 34 | B39: 保险丝 | C39: 熔断型保险丝,12 113.2,1206,2A,ROHS,brightking | D39: 12H 2A 63V | E39: F1 | F39: 1 | G39: =VLOOKUP(C39,[1]物料下单2024!$B$1:$H$65536,7,FALSE) -> 3000
A40: 35 | B40: TVS管 | C40: TVS，SD024C，SOD323 | D40: VCTB24V33D3YW | E40: D301 | F40: 1 | G40: =VLOOKUP(C40,[1]物料下单2024!$B$1:$H$65536,7,FALSE) -> #N/A
A41: 36 | B41: TVS管 | C41: TVS,SMBJ36A,SMB,ROHS，brightking | D41: SMBJ36A | E41: D501 | F41: 1 | G41: =VLOOKUP(C41,[1]物料下单2024!$B$1:$H$65536,7,FALSE) -> 750
A42: 37 | B42: TVS管 | C42: TVSPT3C4V5B，SOD-323,ROHS,PulseTake Devices | D42: VCTB4V5300D3X | E42: D24 | F42: 1 | G42: =VLOOKUP(C42,[1]物料下单2024!$B$1:$H$65536,7,FALSE) -> 3000
A43: 38 | B43: TVS管 | C43: TVS，NUP2105L，SOT23-3,ROHS | D43: NUP2105L | E43: D4 D5 D13 | F43: 3 | G43: =VLOOKUP(C43,[1]物料下单2024!$B$1:$H$65536,7,FALSE) -> 3000
A44: 39 | B44: TVS管 | C44: ESD,5V单向，ESD9L5.0ST5G | D44: VCTU5V0P6D8F | E44: ESD5 ESD6 ESD7 ESD8 ESD9 ESD14 ESD15 ESD16 ESD17 ESD500 ESD501 | F44: 11 | G44: =VLOOKUP(C44,[1]物料下单2024!$B$1:$H$65536,7,FALSE) -> 20000
A45: 40 | B45: 二极管 | C45: 二极管,1N4148WS,100V/150mA,SOD-323 | D45: 1N4148WS | E45: D6 D9 D10 D11 D12 D14 D15 D17 D18 D21 | F45: 10 | G45: =VLOOKUP(C45,[1]物料下单2024!$B$1:$H$65536,7,FALSE) -> #N/A
A46: 41 | B46: 二极管 | C46: 钳位二极管,DAN217U，硅，SOT-323，RoHS | D46: DAN217U | E46: D302 | F46: 1 | G46: =VLOOKUP(C46,[1]物料下单2024!$B$1:$H$65536,7,FALSE) -> #N/A
A47: 42 | B47: 二极管 | C47: 整流二极管,SM360A,DO-214AC(SMA),ROHS | D47: SM360A SMA | E47: D1 D3 D23 | F47: 3 | G47: =VLOOKUP(C47,[1]物料下单2024!$B$1:$H$65536,7,FALSE) -> #N/A
A48: 43 | B48: 二极管 | C48: 二极管, SS34, SMB, ROHS | D48: SS34 SMB | E48: D2 D7 D201 | F48: 3 | G48: =VLOOKUP(C48,[1]物料下单2024!$B$1:$H$65536,7,FALSE) -> 3000
A49: 44 | B49: 三极管 | C49: 三极管,MMBT5551，SOT23，NPN，RoHS | D49: MMBT5551LT1 | E49: Q9 Q10 Q11 | F49: 3 | G49: =VLOOKUP(C49,[1]物料下单2024!$B$1:$H$65536,7,FALSE) -> #N/A
... A56: 51 | B56: IC | C56: IC,SN74LVC2G07DBVR,SOT-23-6,RoHS | D56: RS2G07XH6 | E56: U603 | F56: 1 | G56: =VLOOKUP(C56,[1]物料下单2024!$B$1:$H$65536,7,FALSE) -> #N/A
B57: IC | C57: IC,RS485, SIT3088EESA, SOP8 | D57: SIT3088EESA | E57: U4 U104 | F57: 2
A58: 52 | B58: IC | C58: IC,RS232, SIT3232EEUE, TSSOP16 | D58: BL13232ETS | E58: U9 U504 | F58: 2 | G58: =VLOOKUP(C58,[1]物料下单2024!$B$1:$H$65536,7,FALSE) -> #N/A
A59: 53 | B59: IC | C59: 蓝牙IC, YC1021_QFN32 | D59: YC1021 | E59: U5 | F59: 1 | G59: =VLOOKUP(C59,[1]物料下单2024!$B$1:$H$65536,7,FALSE) -> #N/A
A60: 54 | B60: IC | C60: LTE Cat4模块，EC25AFA-512-STD，ROHS，移远 | D60: EC25AFA-512-STD | E60: U1 | F60: 1 | G60: 450
A61: 55 | B61: IC | C61: WIFI模块, FC20N-Q93, ROHS, 移远 | D61: FC20N-Q93 | E61: U801 | F61: 1 | G61: 472
B62: IC | C62: BT放大器，GSR2401, | D62: QFN16 | E62: U10 | F62: 1
A63: 56 | B63: IC | C63: NORFLASH GD25Q256EYIGR | D63: GD25Q256EYIGR | E63: U103 | F63: 1 | G63: 460
A64: 57 | B64: IC | C64: MCU,GD32F305VCT6,LQFP100,ROHS, | D64: GD32F305VCT6 | E64: U100 | F64: 1 | G64: 540
A65: 58 | B65: 连接器 | C65: 电池座，HYC-CR1220-2，华宇创 | E65: J7 | F65: 1 | G65: =VLOOKUP(C65,[1]物料下单2024!$B$1:$H$65536,7,FALSE) -> 1000
A66: 59 | B66: 连接器 | C66: TYPE-C接口，7.3，SHK16-B130，盛汇康 | E66: J8 | F66: 1 | G66: =VLOOKUP(C66,[1]物料下单2024!$B$1:$H$65536,7,FALSE) -> 1000
A67: 60 | B67: 连接器 | C67: micro PUSH SIM卡座，C792-3无柱H1.5有标6P | E67: J18 | F67: 1 | G67: =VLOOKUP(C67,[1]物料下单2024!$B$1:$H$65536,7,FALSE) -> 1000
...
